<?xml version="1.0"?>


<robot name="brabo" xmlns:xacro="http://www.ros.org/wiki/xacro">


  <!-- Include materials -->

    <material name="Black">
        <color rgba="0.0 0.0 0.0 1.0"/>
    </material>

    <material name="Red">
        <color rgba="0.8 0.0 0.0 1.0"/>
    </material>

    <material name="White">
        <color rgba="1.0 1.0 1.0 1.0"/>
    </material>


  <xacro:property name="deg_to_rad" value="0.01745329251994329577"/>

  <!-- Constants -->
  <xacro:property name="M_SCALE" value="0.001 0.001 0.001"/> 
  <xacro:property name="M_PI" value="3.14159"/>
  <xacro:property name="camera_link" value="0.05" /> <!-- Size of square 'camera' box -->

   <xacro:macro name="inertial_matrix" params="mass">
      <inertial>
      	<mass value="${mass}" />
        <inertia ixx="1.0" ixy="0.0" ixz="0.0" iyy="0.5" iyz="0.0" izz="1.0" />
      </inertial>
   </xacro:macro>

   <xacro:macro name="transmission_block" params="joint_name">
	  <transmission name="tran1_${joint_name}">
	    <type>transmission_interface/SimpleTransmission</type>
	    <joint name="${joint_name}">
	      <hardwareInterface>hardware_interface/PositionJointInterface</hardwareInterface>
	    </joint>
	    <actuator name="motor1_${joint_name}">
	      <hardwareInterface>hardware_interface/PositionJointInterface</hardwareInterface>
	      <mechanicalReduction>1</mechanicalReduction>
	    </actuator>
	  </transmission>
   </xacro:macro>


<!-- BOTTOM FIXED LINK 
This link is the base of the arm in which arm is placed 

-->

<!-- ///////////////////////////////////////////////////////////////////////////////////////////////////////////////////// -->

  <joint name="bottom_joint" type="fixed">
    <origin xyz="0 0 0" rpy="0 0 0" />
    <parent link="base_link"/>
    <child link="bottom_link"/>
  </joint>

  <link name="bottom_link">

    <visual>
      <origin xyz=" 0 0 -0.04"  rpy="0 0 0"/>
      <geometry>

	       <box size="1 1 0.02" />

      </geometry>
      <material name="Brown" />
    </visual>

    <collision>
      <origin xyz=" 0 0 -0.04"  rpy="0 0 0"/>
      <geometry>
	       <box size="1 1 0.02" />
      </geometry>
      </collision>>

  </link>

  <gazebo reference="bottom_link">
    <material>Gazebo/White</material>
  </gazebo>


<!-- ///////////////////////////////////////////////////////////////////////////////////////////////////////////////////// -->

  <!-- BASE LINK -->
  <link name="base_link">

    <visual>
      <origin xyz="0 0 0" rpy="0 0 0" /> <!-- rotate PI/2 -->
      <geometry>

	       <mesh filename="package://brabo_description/meshes/visual/base_link.dae" scale="0.001 0.001 0.001"/>   

      </geometry>
      <material name="Black" />
	  
    </visual>

    <collision>
      <origin xyz="0 0 .025" rpy="0 0 0" /> <!-- rotate PI/2 -->
      <geometry>

	       <cylinder radius=".300" length=".04"/>
		
      </geometry>
      </collision>>
	<xacro:inertial_matrix mass="1"/>

  </link>

  <gazebo reference="base_link">
    <material>Gazebo/White</material>
  </gazebo>

  <joint name="link_1_joint" type="revolute">
    <parent link="base_link"/>
    <child link="link_1"/>
    <origin xyz="0 0 0" rpy="0 0 0" />
    <axis xyz="0 0 1" />
    <limit effort="300" velocity="1" lower="-${M_PI-M_PI/18}" upper="${M_PI-M_PI/18}"/>
    <dynamics damping="50" friction="1"/>
  </joint>


<!-- ///////////////////////////////////////////////////////////////////////////////////////////////////////////////////// -->

  <!-- LINK 1-->
  <link name="link_1" >

    <visual>
      <origin xyz="0 0 0" rpy="0 0 0" />
      <geometry>

            <mesh filename="package://brabo_description/meshes/visual/Link_01.dae" scale="0.001 0.001 0.001"/> 

      </geometry>
      <material name="Red" />
    </visual>

    <collision>
      <origin xyz="0 0 0" rpy="0 0 0" />
      <geometry>
            <mesh filename="package://brabo_description/meshes/visual/Link_01.dae" scale="0.001 0.001 0.001"/> 

      </geometry>
    </collision>
	<xacro:inertial_matrix mass="1"/>
  </link>

  <gazebo reference="link_1">
    <material>Gazebo/Red</material>
  </gazebo>

  <joint name="link_2_joint" type="revolute">
    <parent link="link_1"/>
    <child link="link_2"/>
    <origin xyz="0 0 .459797" rpy="0 -${M_PI/2} 0" />
    <axis xyz="0 0 1" />
    <limit effort="300" velocity="1" lower="-${135*deg_to_rad}" upper="${135*deg_to_rad}" />
    <dynamics damping="50" friction="1"/>
  </joint>

<!-- ///////////////////////////////////////////////////////////////////////////////////////////////////////////////////// -->
  <!-- LINK 2 -->
  <link name="link_2" >

    <visual>
      <origin xyz="-0.459797 0 0" rpy="0 ${M_PI/2} 0" />
      <geometry>

           <mesh filename="package://brabo_description/meshes/visual/Link_02.dae" scale="0.001 0.001 0.001"/> 

      </geometry>
      <material name="White" />
    </visual>

    <collision>
      <origin xyz="-0.459797 0 0" rpy="0 ${M_PI/2} 0" />
      <geometry>
           <mesh filename="package://brabo_description/meshes/visual/Link_02.dae" scale="0.001 0.001 0.001"/> 

      </geometry>
    </collision>
	<xacro:inertial_matrix mass="1"/>
  </link>

  <gazebo reference="link_2">
    <material>Gazebo/White</material>
  </gazebo>

  <joint name="link_3_joint" type="revolute">
    <parent link="link_2"/>
    <child link="link_3"/>
    <origin xyz="0.374934 0 0" rpy="0 ${M_PI} 0 " />
    <axis xyz="0 0 1" />
    <limit effort="300" velocity="1" lower="-${135*deg_to_rad}" upper="${135*deg_to_rad}" />
    <dynamics damping="50" friction="1"/>
  </joint>

<!-- ///////////////////////////////////////////////////////////////////////////////////////////////////////////////////// -->
  <!-- ELBOW ROLL LINK -->
  <link name="link_3" >

    <visual>
      <origin xyz="0.834731 0 0" rpy="0 -${M_PI/2} 0" />
      <geometry>

            <mesh filename="package://brabo_description/meshes/visual/Link_03.dae" scale="0.001 0.001 0.001"/> 

      </geometry>
      <material name="Black" />
    </visual>

    <collision>
      <origin xyz="0.834731 0 0" rpy="0 -${M_PI/2} 0" />
      <geometry>
            <mesh filename="package://brabo_description/meshes/visual/Link_03.dae" scale="0.001 0.001 0.001"/> 

      </geometry>
    </collision>
	<xacro:inertial_matrix mass="1"/>
  </link>

  <gazebo reference="link_3">
    <material>Gazebo/Black</material>
  </gazebo>

  <joint name="link_4_joint" type="revolute">
    <parent link="link_3"/>
    <child link="link_4"/>
    <origin xyz="-0.375066 0 0" rpy="0 0 0" />
    <axis xyz="0 0 1" />
    <limit effort="300" velocity="1" lower="-${M_PI*2}" upper="${M_PI*2}" />
    <dynamics damping="50" friction="1"/>
  </joint>

<!-- ///////////////////////////////////////////////////////////////////////////////////////////////////////////////////// -->

  <!-- ELBOW PITCH LINK -->
  <link name="link_4" >

    <visual>
      <origin xyz="1.209797 0 0" rpy="0 -${M_PI/2} 0" />
      <geometry>

        <mesh filename="package://brabo_description/meshes/visual/Link_04.dae" scale="0.001 0.001 0.001"/> 

      </geometry>
      <material name="Red" />
    </visual>

    <collision>
      <origin xyz="1.209797 0 0" rpy="0 -${M_PI/2} 0" />
      <geometry>
       <mesh filename="package://brabo_description/meshes/visual/Link_04.dae" scale="0.001 0.001 0.001"/> 

      </geometry>
    </collision>
	<xacro:inertial_matrix mass="1"/>
  </link>

  <gazebo reference="link_4">
    <material>Gazebo/Red</material>
  </gazebo>

  <joint name="link_5_joint" type="revolute">
    <parent link="link_4"/>
    <child link="link_5"/>
    <origin xyz="0 0 0" rpy="0 -${M_PI/2} 0" />
    <axis xyz="0 0 1" />
    <limit effort="300" velocity="1" lower="-2.61799387799" upper="2.6128806087" />
    <dynamics damping="50" friction="1"/>
  </joint>

  <!-- WRIST ROLL LINK -->
  <link name="link_5" >
    <visual>
      <origin xyz="0 0 -1.209797" rpy="0 0 0" />
      <geometry>

         <mesh filename="package://brabo_description/meshes/visual/Link_05.dae" scale="0.001 0.001 0.001"/> 

      </geometry>
      <material name="Black" />
    </visual>

    <collision>
      <origin xyz="0 0 -1.209797" rpy="0 0 0" />
      <geometry>
           <mesh filename="package://brabo_description/meshes/visual/Link_05.dae" scale="0.001 0.001 0.001"/> 

      </geometry>
    </collision>
	<xacro:inertial_matrix mass="1"/>

  </link>

  <gazebo reference="link_5">
    <material>Gazebo/Black</material>
  </gazebo>

   <joint name="camera_joint" type="fixed">
    <axis xyz="0 1 0" />
    <origin xyz="0 0 0.075" rpy="0 0 0"/>
    <parent link="link_5"/>
    <child link="camera_link"/>
  </joint>

  <!-- Camera -->
  <link name="camera_link">
    <collision>
      <origin xyz="0 0 0" rpy="0 0 0"/>
      <geometry>
    <box size="${camera_link} ${camera_link} ${camera_link}"/>
      </geometry>
    </collision>

    <visual>
      <origin xyz="0 0 0" rpy="0 0 0"/>
      <geometry>
    <box size="${camera_link} ${camera_link} ${camera_link}"/>
      </geometry>
      <material name="red"/>
    </visual>

    <inertial>
      <mass value="1e-5" />
      <origin xyz="0 0 0" rpy="0 0 0"/>
      <inertia ixx="1e-6" ixy="0" ixz="0" iyy="1e-6" iyz="0" izz="1e-6" />
    </inertial>
  </link>


<!-- ///////////////////////////////////////////////////////////////////////////////////////////////////////////////////// -->
  <!-- Transmissions for ROS Control -->

   <xacro:transmission_block joint_name="link_1_joint"/>
   <xacro:transmission_block joint_name="link_2_joint"/>
   <xacro:transmission_block joint_name="link_3_joint"/>
   <xacro:transmission_block joint_name="link_4_joint"/>
   <xacro:transmission_block joint_name="link_5_joint"/>



  <!-- Define arm with gripper mounted on a base -->
  <!-- <xacro:base name="base"/> 
  <xacro:arm parent="base"/> 
  <xacro:gripper parent="tool"/> -->

  

  <!-- ros_control plugin -->
  <gazebo>
    <plugin name="gazebo_ros_control" filename="libgazebo_ros_control.so">
      <robotNamespace>/brabo</robotNamespace>
      <robotSimType>gazebo_ros_control/DefaultRobotHWSim</robotSimType>
<legacyModeNS>true</legacyModeNS>
    </plugin>
  </gazebo>

  <!-- camera -->
  <gazebo reference="camera_link">
    <sensor type="camera" name="camera1">
      <update_rate>30.0</update_rate>
      <camera name="head">
        <horizontal_fov>1.3962634</horizontal_fov>
        <image>
          <width>800</width>
          <height>800</height>
          <format>R8G8B8</format>
        </image>
        <clip>
          <near>0.02</near>
          <far>300</far>
        </clip>
        <noise>
          <type>gaussian</type>
          <!-- Noise is sampled independently per pixel on each frame.
               That pixel's noise value is added to each of its color
               channels, which at that point lie in the range [0,1]. -->
          <mean>0.0</mean>
          <stddev>0.007</stddev>
        </noise>
      </camera>
      <plugin name="camera_controller" filename="libgazebo_ros_camera.so">
        <alwaysOn>true</alwaysOn>
        <updateRate>0.0</updateRate>
        <cameraName>rrbot/camera1</cameraName>
        <imageTopicName>image_raw</imageTopicName>
        <cameraInfoTopicName>camera_info</cameraInfoTopicName>
        <frameName>camera_link</frameName>
        <hackBaseline>0.07</hackBaseline>
        <distortionK1>0.0</distortionK1>
        <distortionK2>0.0</distortionK2>
        <distortionK3>0.0</distortionK3>
        <distortionT1>0.0</distortionT1>
        <distortionT2>0.0</distortionT2>
      </plugin>
    </sensor>
  </gazebo>

</robot>
